I crashed :(   'dict' object has no attribute 'village'
Traceback (most recent call last):
  File "/Volumes/storage/game/tw/shalum-br37/twb.py", line 445, in main
    t.start()
    ~~~~~~~^^
  File "/Volumes/storage/game/tw/shalum-br37/twb.py", line 434, in start
    self.run()
    ~~~~~~~~^^
  File "/Volumes/storage/game/tw/shalum-br37/twb.py", line 379, in run
    village.run(config=config)
    ~~~~~~~~~~~^^^^^^^^^^^^^^^
  File "/Volumes/storage/game/tw/shalum-br37/game/village.py", line 596, in run
    self.run_farming()
    ~~~~~~~~~~~~~~~~^^
  File "/Volumes/storage/game/tw/shalum-br37/game/village.py", line 493, in run_farming
    self.attack.run()
    ~~~~~~~~~~~~~~~^^
  File "/Volumes/storage/game/tw/shalum-br37/game/attack.py", line 86, in run
    out_res = self.send_farm(target, template)
  File "/Volumes/storage/game/tw/shalum-br37/game/attack.py", line 106, in send_farm
    cached = self.can_attack(vid=target["id"], clear=False)
  File "/Volumes/storage/game/tw/shalum-br37/game/attack.py", line 262, in can_attack
    if self.scout(vid):
       ~~~~~~~~~~^^^^^
  File "/Volumes/storage/game/tw/shalum-br37/game/attack.py", line 247, in scout
    if self.attack(vid, troops=troops):
       ~~~~~~~~~~~^^^^^^^^^^^^^^^^^^^^
  File "/Volumes/storage/game/tw/shalum-br37/game/attack.py", line 390, in attack
    if self.has_owner_now(x, y) and vid not in self.extra_farm:
       ~~~~~~~~~~~~~~~~~~^^^^^^
  File "/Volumes/storage/game/tw/shalum-br37/game/attack.py", line 362, in has_owner_now
    player_id = response.village[0].player_id
                ^^^^^^^^^^^^^^^^
